Workbook
Name Slicer_Admin_Era: #N/A
Name Slicer_Company_name: #N/A
Name Slicer_Node_Category: #N/A
Name Slicer_Year: #N/A

Sheet OBJECTIVE
A1: Project Title
A2: Semiconductor Industry Intelligence Dashboard — a one-page interactive Excel dashboard that lets any viewer slice through 5 datasets and instantly understand where the global chip industry is, where it is going, and what risks threaten it.
A4: Project Objective
A5: To analyse and visualise the global semiconductor industry across four dimensions — AI chip market dynamics, company financial performance, worldwide fab manufacturing capacity, and geopolitical export control risks — so that a hiring manager or business stakeholder can make informed decisions by interacting with a single dashboard.
A7: Four business questions this dashboard answers
A8: Which AI chip vendors are winning the market, and how fast is revenue growing?
A9: Which companies are financially strongest — who has the best margins, highest R&D investment, and most efficient capex?
A10: How is global semiconductor manufacturing capacity distributed — which countries and process nodes dominate?
A11: How are US-China export controls escalating, and what is their severity over time?

Sheet Dashboard
A1: SEMICONDUCTOR INDUSTRY INTELLIGENCE DASHBOARD
A2: GLOBAL SEMICONDUCTOR ANALYSIS | 5 REAL DATASETS | KAGGLE
A4: Total Industry Revenue 2024 | G4: Highest Op. margin 2024 | M4: NVIDIA H100 Peak Price | S4: Export Control Actions
C6: =CALC!B2 -> 828.51 | I6: =CALC!B3 -> 59.5 | O6: =CALC!B4 -> 35640.01 | U6: =CALC!B5 -> 34

Sheet RAW_AI
A1: Year | B1: Chip_Name | C1: Vendor | D1: Launch_Date | E1: Memory_gb | F1: fp16_tflops | G1: tdp_watts | H1: Estimated_shipments_units | I1: Estimated_asp_usd | J1: Estimated_revenue_usd_m | K1: description | L1: Revenue Category | M1: Perf_Per_Watt
A2: 2020 | B2: NVIDIA V100 | C2: NVIDIA | D2: 42865 | E2: 32 | F2: 100 | G2: 300 | H2: 6128 | I2: 15000 | J2: 91.9 | K2: Volta data center GPU | L2: =IF(J2>500,"High",IF(J2>100,"Medium","Low")) -> Low | M2: =F2/G2 -> 0.33333333
A3: 2021 | B3: NVIDIA V100 | C3: NVIDIA | D3: 42865 | E3: 32 | F3: 100 | G3: 300 | H3: 2719 | I3: 15000 | J3: 40.8 | K3: Volta data center GPU | L3: =IF(J3>500,"High",IF(J3>100,"Medium","Low")) -> Low | M3: =F3/G3 -> 0.33333333
A4: 2022 | B4: NVIDIA V100 | C4: NVIDIA | D4: 42865 | E4: 32 | F4: 100 | G4: 300 | H4: 3098 | I4: 15000 | J4: 46.5 | K4: Volta data center GPU | L4: =IF(J4>500,"High",IF(J4>100,"Medium","Low")) -> Low | M4: =F4/G4 -> 0.33333333
A5: 2023 | B5: NVIDIA V100 | C5: NVIDIA | D5: 42865 | E5: 32 | F5: 100 | G5: 300 | H5: 2572 | I5: 15000 | J5: 38.6 | K5: Volta data center GPU | L5: =IF(J5>500,"High",IF(J5>100,"Medium","Low")) -> Low | M5: =F5/G5 -> 0.33333333
A6: 2024 | B6: NVIDIA V100 | C6: NVIDIA | D6: 42865 | E6: 32 | F6: 100 | G6: 300 | H6: 3437 | I6: 15000 | J6: 51.6 | K6: Volta data center GPU | L6: =IF(J6>500,"High",IF(J6>100,"Medium","Low")) -> Low | M6: =F6/G6 -> 0.33333333
A7: 2025 | B7: NVIDIA V100 | C7: NVIDIA | D7: 42865 | E7: 32 | F7: 100 | G7: 300 | H7: 2504 | I7: 15000 | J7: 37.6 | K7: Volta data center GPU | L7: =IF(J7>500,"High",IF(J7>100,"Medium","Low")) -> Low | M7: =F7/G7 -> 0.33333333
A8: 2026 | B8: NVIDIA V100 | C8: NVIDIA | D8: 42865 | E8: 32 | F8: 100 | G8: 300 | H8: 2873 | I8: 15000 | J8: 43.1 | K8: Volta data center GPU | L8: =IF(J8>500,"High",IF(J8>100,"Medium","Low")) -> Low | M8: =F8/G8 -> 0.33333333
A9: 2020 | B9: NVIDIA A100 | C9: NVIDIA | D9: 43965 | E9: 40 | F9: 312 | G9: 400 | H9: 32054 | I9: 15000 | J9: 480.8 | K9: Ampere, ML training standard 2020-2022 | L9: =IF(J9>500,"High",IF(J9>100,"Medium","Low")) -> Medium | M9: =F9/G9 -> 0.78
A10: 2021 | B10: NVIDIA A100 | C10: NVIDIA | D10: 43965 | E10: 40 | F10: 312 | G10: 400 | H10: 204990 | I10: 15000 | J10: 3074.8 | K10: Ampere, ML training standard 2020-2022 | L10: =IF(J10>500,"High",IF(J10>100,"Medium","Low")) -> High | M10: =F10/G10 -> 0.78
A11: 2022 | B11: NVIDIA A100 | C11: NVIDIA | D11: 43965 | E11: 40 | F11: 312 | G11: 400 | H11: 145343 | I11: 15000 | J11: 2180.1 | K11: Ampere, ML training standard 2020-2022 | L11: =IF(J11>500,"High",IF(J11>100,"Medium","Low")) -> High | M11: =F11/G11 -> 0.78
A12: 2023 | B12: NVIDIA A100 | C12: NVIDIA | D12: 43965 | E12: 40 | F12: 312 | G12: 400 | H12: 76814 | I12: 15000 | J12: 1152.2 | K12: Ampere, ML training standard 2020-2022 | L12: =IF(J12>500,"High",IF(J12>100,"Medium","Low")) -> High | M12: =F12/G12 -> 0.78
A13: 2024 | B13: NVIDIA A100 | C13: NVIDIA | D13: 43965 | E13: 40 | F13: 312 | G13: 400 | H13: 28956 | I13: 15000 | J13: 434.3 | K13: Ampere, ML training standard 2020-2022 | L13: =IF(J13>500,"High",IF(J13>100,"Medium","Low")) -> Medium | M13: =F13/G13 -> 0.78
... A121: 2026 | B121: Apple M5 (NPU) | C121: Apple | D121: 45960 | E121: 16 | F121: 60 | G121: 28 | H121: 809 | I121: 15000 | J121: 12.1 | K121: M5 NPU generation | L121: =IF(J121>500,"High",IF(J121>100,"Medium","Low")) -> Low | M121: =F121/G121 -> 2.1428571

Sheet RAW_Fin
A1: Year | B1: Company_name | C1: Ticker | D1: Country_iso3 | E1: Segment | F1: Revenue_usd_bn | G1: Operating_margin_pct | H1: Operating_income_usd_bn | I1: Rd_spend_usd_bn | J1: Capex_usd_bn | K1: Data_Type | L1: RD_Intensity_pct | M1: Capex_Intensity_pct | N1: Company_Type
A2: 2010 | B2: TSMC | C2: TSM | D2: TWN | E2: foundry | F2: 13.42 | G2: 36.9 | H2: 4.95 | I2: 1.07 | J2: 6.04 | K2: =IF(A2>=2025,"Forecast","Actual") -> Actual | L2: =IF(F2=0,0,I2/F2*100) -> 7.9731744 | M2: =IF(F2=0,0,J2/F2*100) -> 45.007452 | N2: =IF(LEFT(E2,7)="fabless","Fabless",IF(LEFT(E2,9)="equipment","Equipment",IF(E2="foundry","Manufacturer",IF(LEFT(E2,3)="idm","Manufacturer",IF(E2="eda_software","EDA Software","Other"))))) -> Manufacturer
A3: 2011 | B3: TSMC | C3: TSM | D3: TWN | E3: foundry | F3: 16.32 | G3: 42.8 | H3: 6.99 | I3: 1.31 | J3: 7.35 | K3: =IF(A3>=2025,"Forecast","Actual") -> Actual | L3: =IF(F3=0,0,I3/F3*100) -> 8.0269608 | M3: =IF(F3=0,0,J3/F3*100) -> 45.036765 | N3: =IF(LEFT(E3,7)="fabless","Fabless",IF(LEFT(E3,9)="equipment","Equipment",IF(E3="foundry","Manufacturer",IF(LEFT(E3,3)="idm","Manufacturer",IF(E3="eda_software","EDA Software","Other"))))) -> Manufacturer
A4: 2012 | B4: TSMC | C4: TSM | D4: TWN | E4: foundry | F4: 17.56 | G4: 36.1 | H4: 6.34 | I4: 1.4 | J4: 7.9 | K4: =IF(A4>=2025,"Forecast","Actual") -> Actual | L4: =IF(F4=0,0,I4/F4*100) -> 7.9726651 | M4: =IF(F4=0,0,J4/F4*100) -> 44.98861 | N4: =IF(LEFT(E4,7)="fabless","Fabless",IF(LEFT(E4,9)="equipment","Equipment",IF(E4="foundry","Manufacturer",IF(LEFT(E4,3)="idm","Manufacturer",IF(E4="eda_software","EDA Software","Other"))))) -> Manufacturer
A5: 2013 | B5: TSMC | C5: TSM | D5: TWN | E5: foundry | F5: 21.36 | G5: 39.1 | H5: 8.34 | I5: 1.71 | J5: 9.61 | K5: =IF(A5>=2025,"Forecast","Actual") -> Actual | L5: =IF(F5=0,0,I5/F5*100) -> 8.005618 | M5: =IF(F5=0,0,J5/F5*100) -> 44.990637 | N5: =IF(LEFT(E5,7)="fabless","Fabless",IF(LEFT(E5,9)="equipment","Equipment",IF(E5="foundry","Manufacturer",IF(LEFT(E5,3)="idm","Manufacturer",IF(E5="eda_software","EDA Software","Other"))))) -> Manufacturer
A6: 2014 | B6: TSMC | C6: TSM | D6: TWN | E6: foundry | F6: 23.93 | G6: 37.4 | H6: 8.96 | I6: 1.91 | J6: 10.77 | K6: =IF(A6>=2025,"Forecast","Actual") -> Actual | L6: =IF(F6=0,0,I6/F6*100) -> 7.981613 | M6: =IF(F6=0,0,J6/F6*100) -> 45.006268 | N6: =IF(LEFT(E6,7)="fabless","Fabless",IF(LEFT(E6,9)="equipment","Equipment",IF(E6="foundry","Manufacturer",IF(LEFT(E6,3)="idm","Manufacturer",IF(E6="eda_software","EDA Software","Other"))))) -> Manufacturer
A7: 2015 | B7: TSMC | C7: TSM | D7: TWN | E7: foundry | F7: 27.31 | G7: 42.3 | H7: 11.56 | I7: 2.18 | J7: 12.29 | K7: =IF(A7>=2025,"Forecast","Actual") -> Actual | L7: =IF(F7=0,0,I7/F7*100) -> 7.982424 | M7: =IF(F7=0,0,J7/F7*100) -> 45.001831 | N7: =IF(LEFT(E7,7)="fabless","Fabless",IF(LEFT(E7,9)="equipment","Equipment",IF(E7="foundry","Manufacturer",IF(LEFT(E7,3)="idm","Manufacturer",IF(E7="eda_software","EDA Software","Other"))))) -> Manufacturer
A8: 2016 | B8: TSMC | C8: TSM | D8: TWN | E8: foundry | F8: 29.19 | G8: 43.4 | H8: 12.66 | I8: 2.34 | J8: 13.14 | K8: =IF(A8>=2025,"Forecast","Actual") -> Actual | L8: =IF(F8=0,0,I8/F8*100) -> 8.016444 | M8: =IF(F8=0,0,J8/F8*100) -> 45.015416 | N8: =IF(LEFT(E8,7)="fabless","Fabless",IF(LEFT(E8,9)="equipment","Equipment",IF(E8="foundry","Manufacturer",IF(LEFT(E8,3)="idm","Manufacturer",IF(E8="eda_software","EDA Software","Other"))))) -> Manufacturer
A9: 2017 | B9: TSMC | C9: TSM | D9: TWN | E9: foundry | F9: 32.11 | G9: 37.4 | H9: 12.02 | I9: 2.57 | J9: 14.45 | K9: =IF(A9>=2025,"Forecast","Actual") -> Actual | L9: =IF(F9=0,0,I9/F9*100) -> 8.0037372 | M9: =IF(F9=0,0,J9/F9*100) -> 45.001557 | N9: =IF(LEFT(E9,7)="fabless","Fabless",IF(LEFT(E9,9)="equipment","Equipment",IF(E9="foundry","Manufacturer",IF(LEFT(E9,3)="idm","Manufacturer",IF(E9="eda_software","EDA Software","Other"))))) -> Manufacturer
A10: 2018 | B10: TSMC | C10: TSM | D10: TWN | E10: foundry | F10: 34.58 | G10: 37.1 | H10: 12.84 | I10: 2.77 | J10: 15.56 | K10: =IF(A10>=2025,"Forecast","Actual") -> Actual | L10: =IF(F10=0,0,I10/F10*100) -> 8.0104106 | M10: =IF(F10=0,0,J10/F10*100) -> 44.997108 | N10: =IF(LEFT(E10,7)="fabless","Fabless",IF(LEFT(E10,9)="equipment","Equipment",IF(E10="foundry","Manufacturer",IF(LEFT(E10,3)="idm","Manufacturer",IF(E10="eda_software","EDA Software","Other"))))) -> Manufacturer
A11: 2019 | B11: TSMC | C11: TSM | D11: TWN | E11: foundry | F11: 40.91 | G11: 39.9 | H11: 16.3 | I11: 3.27 | J11: 18.41 | K11: =IF(A11>=2025,"Forecast","Actual") -> Actual | L11: =IF(F11=0,0,I11/F11*100) -> 7.9931557 | M11: =IF(F11=0,0,J11/F11*100) -> 45.001222 | N11: =IF(LEFT(E11,7)="fabless","Fabless",IF(LEFT(E11,9)="equipment","Equipment",IF(E11="foundry","Manufacturer",IF(LEFT(E11,3)="idm","Manufacturer",IF(E11="eda_software","EDA Software","Other"))))) -> Manufacturer
A12: 2020 | B12: TSMC | C12: TSM | D12: TWN | E12: foundry | F12: 45.25 | G12: 38 | H12: 17.18 | I12: 3.62 | J12: 20.36 | K12: =IF(A12>=2025,"Forecast","Actual") -> Actual | L12: =IF(F12=0,0,I12/F12*100) -> 8 | M12: =IF(F12=0,0,J12/F12*100) -> 44.994475 | N12: =IF(LEFT(E12,7)="fabless","Fabless",IF(LEFT(E12,9)="equipment","Equipment",IF(E12="foundry","Manufacturer",IF(LEFT(E12,3)="idm","Manufacturer",IF(E12="eda_software","EDA Software","Other"))))) -> Manufacturer
A13: 2021 | B13: TSMC | C13: TSM | D13: TWN | E13: foundry | F13: 62.97 | G13: 39.5 | H13: 24.9 | I13: 5.04 | J13: 28.34 | K13: =IF(A13>=2025,"Forecast","Actual") -> Actual | L13: =IF(F13=0,0,I13/F13*100) -> 8.0038113 | M13: =IF(F13=0,0,J13/F13*100) -> 45.005558 | N13: =IF(LEFT(E13,7)="fabless","Fabless",IF(LEFT(E13,9)="equipment","Equipment",IF(E13="foundry","Manufacturer",IF(LEFT(E13,3)="idm","Manufacturer",IF(E13="eda_software","EDA Software","Other"))))) -> Manufacturer
... A154: 2026 | B154: Broadcom | C154: AVGO | D154: USA | E154: fabless_diversified | F154: 69.87 | G154: 26.8 | H154: 18.75 | I154: 8.38 | J154: 6.99 | K154: =IF(A154>=2025,"Forecast","Actual") -> Forecast | L154: =IF(F154=0,0,I154/F154*100) -> 11.993703 | M154: =IF(F154=0,0,J154/F154*100) -> 10.004294 | N154: =IF(LEFT(E154,7)="fabless","Fabless",IF(LEFT(E154,9)="equipment","Equipment",IF(E154="foundry","Manufacturer",IF(LEFT(E154,3)="idm","Manufacturer",IF(E154="eda_software","EDA Software","Other"))))) -> Fabless
A155: 2010 | B155: MediaTek | C155: 2454 | D155: TWN | E155: fabless_mobile | F155: 3.56 | G155: 33.9 | H155: 1.21 | I155: 0.43 | J155: 0.36 | K155: =IF(A155>=2025,"Forecast","Actual") -> Actual | L155: =IF(F155=0,0,I155/F155*100) -> 12.078652 | M155: =IF(F155=0,0,J155/F155*100) -> 10.11236 | N155: =IF(LEFT(E155,7)="fabless","Fabless",IF(LEFT(E155,9)="equipment","Equipment",IF(E155="foundry","Manufacturer",IF(LEFT(E155,3)="idm","Manufacturer",IF(E155="eda_software","EDA Software","Other"))))) -> Fabless
A156: 2011 | B156: MediaTek | C156: 2454 | D156: TWN | E156: fabless_mobile | F156: 4.23 | G156: 35.2 | H156: 1.49 | I156: 0.51 | J156: 0.42 | K156: =IF(A156>=2025,"Forecast","Actual") -> Actual | L156: =IF(F156=0,0,I156/F156*100) -> 12.056738 | M156: =IF(F156=0,0,J156/F156*100) -> 9.929078 | N156: =IF(LEFT(E156,7)="fabless","Fabless",IF(LEFT(E156,9)="equipment","Equipment",IF(E156="foundry","Manufacturer",IF(LEFT(E156,3)="idm","Manufacturer",IF(E156="eda_software","EDA Software","Other"))))) -> Fabless
A157: 2012 | B157: MediaTek | C157: 2454 | D157: TWN | E157: fabless_mobile | F157: 4.89 | G157: 31.3 | H157: 1.53 | I157: 0.59 | J157: 0.49 | K157: =IF(A157>=2025,"Forecast","Actual") -> Actual | L157: =IF(F157=0,0,I157/F157*100) -> 12.06544 | M157: =IF(F157=0,0,J157/F157*100) -> 10.02045 | N157: =IF(LEFT(E157,7)="fabless","Fabless",IF(LEFT(E157,9)="equipment","Equipment",IF(E157="foundry","Manufacturer",IF(LEFT(E157,3)="idm","Manufacturer",IF(E157="eda_software","EDA Software","Other"))))) -> Fabless
A158: 2013 | B158: MediaTek | C158: 2454 | D158: TWN | E158: fabless_mobile | F158: 5.56 | G158: 31.3 | H158: 1.74 | I158: 0.67 | J158: 0.56 | K158: =IF(A158>=2025,"Forecast","Actual") -> Actual | L158: =IF(F158=0,0,I158/F158*100) -> 12.05036 | M158: =IF(F158=0,0,J158/F158*100) -> 10.071942 | N158: =IF(LEFT(E158,7)="fabless","Fabless",IF(LEFT(E158,9)="equipment","Equipment",IF(E158="foundry","Manufacturer",IF(LEFT(E158,3)="idm","Manufacturer",IF(E158="eda_software","EDA Software","Other"))))) -> Fabless
A159: 2014 | B159: MediaTek | C159: 2454 | D159: TWN | E159: fabless_mobile | F159: 5.99 | G159: 29.1 | H159: 1.74 | I159: 0.72 | J159: 0.6 | K159: =IF(A159>=2025,"Forecast","Actual") -> Actual | L159: =IF(F159=0,0,I159/F159*100) -> 12.020033 | M159: =IF(F159=0,0,J159/F159*100) -> 10.016694 | N159: =IF(LEFT(E159,7)="fabless","Fabless",IF(LEFT(E159,9)="equipment","Equipment",IF(E159="foundry","Manufacturer",IF(LEFT(E159,3)="idm","Manufacturer",IF(E159="eda_software","EDA Software","Other"))))) -> Fabless
A160: 2015 | B160: MediaTek | C160: 2454 | D160: TWN | E160: fabless_mobile | F160: 6.41 | G160: 27.9 | H160: 1.79 | I160: 0.77 | J160: 0.64 | K160: =IF(A160>=2025,"Forecast","Actual") -> Actual | L160: =IF(F160=0,0,I160/F160*100) -> 12.01248 | M160: =IF(F160=0,0,J160/F160*100) -> 9.9843994 | N160: =IF(LEFT(E160,7)="fabless","Fabless",IF(LEFT(E160,9)="equipment","Equipment",IF(E160="foundry","Manufacturer",IF(LEFT(E160,3)="idm","Manufacturer",IF(E160="eda_software","EDA Software","Other"))))) -> Fabless
A161: 2016 | B161: MediaTek | C161: 2454 | D161: TWN | E161: fabless_mobile | F161: 7 | G161: 26.5 | H161: 1.85 | I161: 0.84 | J161: 0.7 | K161: =IF(A161>=2025,"Forecast","Actual") -> Actual | L161: =IF(F161=0,0,I161/F161*100) -> 12 | M161: =IF(F161=0,0,J161/F161*100) -> 10 | N161: =IF(LEFT(E161,7)="fabless","Fabless",IF(LEFT(E161,9)="equipment","Equipment",IF(E161="foundry","Manufacturer",IF(LEFT(E161,3)="idm","Manufacturer",IF(E161="eda_software","EDA Software","Other"))))) -> Fabless
A162: 2017 | B162: MediaTek | C162: 2454 | D162: TWN | E162: fabless_mobile | F162: 7.37 | G162: 29.4 | H162: 2.17 | I162: 0.88 | J162: 0.74 | K162: =IF(A162>=2025,"Forecast","Actual") -> Actual | L162: =IF(F162=0,0,I162/F162*100) -> 11.940299 | M162: =IF(F162=0,0,J162/F162*100) -> 10.040706 | N162: =IF(LEFT(E162,7)="fabless","Fabless",IF(LEFT(E162,9)="equipment","Equipment",IF(E162="foundry","Manufacturer",IF(LEFT(E162,3)="idm","Manufacturer",IF(E162="eda_software","EDA Software","Other"))))) -> Fabless
A163: 2018 | B163: MediaTek | C163: 2454 | D163: TWN | E163: fabless_mobile | F163: 7.87 | G163: 32.3 | H163: 2.54 | I163: 0.94 | J163: 0.79 | K163: =IF(A163>=2025,"Forecast","Actual") -> Actual | L163: =IF(F163=0,0,I163/F163*100) -> 11.944091 | M163: =IF(F163=0,0,J163/F163*100) -> 10.038119 | N163: =IF(LEFT(E163,7)="fabless","Fabless",IF(LEFT(E163,9)="equipment","Equipment",IF(E163="foundry","Manufacturer",IF(LEFT(E163,3)="idm","Manufacturer",IF(E163="eda_software","EDA Software","Other"))))) -> Fabless
A164: 2019 | B164: MediaTek | C164: 2454 | D164: TWN | E164: fabless_mobile | F164: 9.77 | G164: 32.2 | H164: 3.14 | I164: 1.17 | J164: 0.98 | K164: =IF(A164>=2025,"Forecast","Actual") -> Actual | L164: =IF(F164=0,0,I164/F164*100) -> 11.975435 | M164: =IF(F164=0,0,J164/F164*100) -> 10.030706 | N164: =IF(LEFT(E164,7)="fabless","Fabless",IF(LEFT(E164,9)="equipment","Equipment",IF(E164="foundry","Manufacturer",IF(LEFT(E164,3)="idm","Manufacturer",IF(E164="eda_software","EDA Software","Other"))))) -> Fabless
A165: 2020 | B165: MediaTek | C165: 2454 | D165: TWN | E165: fabless_mobile | F165: 10.4 | G165: 29.8 | H165: 3.1 | I165: 1.25 | J165: 1.04 | K165: =IF(A165>=2025,"Forecast","Actual") -> Actual | L165: =IF(F165=0,0,I165/F165*100) -> 12.019231 | M165: =IF(F165=0,0,J165/F165*100) -> 10 | N165: =IF(LEFT(E165,7)="fabless","Fabless",IF(LEFT(E165,9)="equipment","Equipment",IF(E165="foundry","Manufacturer",IF(LEFT(E165,3)="idm","Manufacturer",IF(E165="eda_software","EDA Software","Other"))))) -> Fabless
A166: 2021 | B166: MediaTek | C166: 2454 | D166: TWN | E166: fabless_mobile | F166: 14.24 | G166: 28.4 | H166: 4.05 | I166: 1.71 | J166: 1.42 | K166: =IF(A166>=2025,"Forecast","Actual") -> Actual | L166: =IF(F166=0,0,I166/F166*100) -> 12.008427 | M166: =IF(F166=0,0,J166/F166*100) -> 9.9719101 | N166: =IF(LEFT(E166,7)="fabless","Fabless",IF(LEFT(E166,9)="equipment","Equipment",IF(E166="foundry","Manufacturer",IF(LEFT(E166,3)="idm","Manufacturer",IF(E166="eda_software","EDA Software","Other"))))) -> Fabless
... A171: 2026 | B171: MediaTek | C171: 2454 | D171: TWN | E171: fabless_mobile | F171: 21.74 | G171: 31.8 | H171: 6.92 | I171: 2.61 | J171: 2.17 | K171: =IF(A171>=2025,"Forecast","Actual") -> Forecast | L171: =IF(F171=0,0,I171/F171*100) -> 12.00552 | M171: =IF(F171=0,0,J171/F171*100) -> 9.9816007 | N171: =IF(LEFT(E171,7)="fabless","Fabless",IF(LEFT(E171,9)="equipment","Equipment",IF(E171="foundry","Manufacturer",IF(LEFT(E171,3)="idm","Manufacturer",IF(E171="eda_software","EDA Software","Other"))))) -> Fabless
A172: 2010 | B172: Marvell | C172: MRVL | D172: USA | E172: fabless_networking | F172: 3.36 | G172: 25.9 | H172: 0.87 | I172: 0.4 | J172: 0.34 | K172: =IF(A172>=2025,"Forecast","Actual") -> Actual | L172: =IF(F172=0,0,I172/F172*100) -> 11.904762 | M172: =IF(F172=0,0,J172/F172*100) -> 10.119048 | N172: =IF(LEFT(E172,7)="fabless","Fabless",IF(LEFT(E172,9)="equipment","Equipment",IF(E172="foundry","Manufacturer",IF(LEFT(E172,3)="idm","Manufacturer",IF(E172="eda_software","EDA Software","Other"))))) -> Fabless
A173: 2011 | B173: Marvell | C173: MRVL | D173: USA | E173: fabless_networking | F173: 3.43 | G173: 26.2 | H173: 0.9 | I173: 0.41 | J173: 0.34 | K173: =IF(A173>=2025,"Forecast","Actual") -> Actual | L173: =IF(F173=0,0,I173/F173*100) -> 11.953353 | M173: =IF(F173=0,0,J173/F173*100) -> 9.9125364 | N173: =IF(LEFT(E173,7)="fabless","Fabless",IF(LEFT(E173,9)="equipment","Equipment",IF(E173="foundry","Manufacturer",IF(LEFT(E173,3)="idm","Manufacturer",IF(E173="eda_software","EDA Software","Other"))))) -> Fabless
A174: 2012 | B174: Marvell | C174: MRVL | D174: USA | E174: fabless_networking | F174: 3.4 | G174: 18.8 | H174: 0.64 | I174: 0.41 | J174: 0.34 | K174: =IF(A174>=2025,"Forecast","Actual") -> Actual | L174: =IF(F174=0,0,I174/F174*100) -> 12.058824 | M174: =IF(F174=0,0,J174/F174*100) -> 10 | N174: =IF(LEFT(E174,7)="fabless","Fabless",IF(LEFT(E174,9)="equipment","Equipment",IF(E174="foundry","Manufacturer",IF(LEFT(E174,3)="idm","Manufacturer",IF(E174="eda_software","EDA Software","Other"))))) -> Fabless
A175: 2013 | B175: Marvell | C175: MRVL | D175: USA | E175: fabless_networking | F175: 3.01 | G175: 26.8 | H175: 0.8 | I175: 0.36 | J175: 0.3 | K175: =IF(A175>=2025,"Forecast","Actual") -> Actual | L175: =IF(F175=0,0,I175/F175*100) -> 11.960133 | M175: =IF(F175=0,0,J175/F175*100) -> 9.9667774 | N175: =IF(LEFT(E175,7)="fabless","Fabless",IF(LEFT(E175,9)="equipment","Equipment",IF(E175="foundry","Manufacturer",IF(LEFT(E175,3)="idm","Manufacturer",IF(E175="eda_software","EDA Software","Other"))))) -> Fabless
A176: 2014 | B176: Marvell | C176: MRVL | D176: USA | E176: fabless_networking | F176: 2.75 | G176: 29.4 | H176: 0.81 | I176: 0.33 | J176: 0.27 | K176: =IF(A176>=2025,"Forecast","Actual") -> Actual | L176: =IF(F176=0,0,I176/F176*100) -> 12 | M176: =IF(F176=0,0,J176/F176*100) -> 9.8181818 | N176: =IF(LEFT(E176,7)="fabless","Fabless",IF(LEFT(E176,9)="equipment","Equipment",IF(E176="foundry","Manufacturer",IF(LEFT(E176,3)="idm","Manufacturer",IF(E176="eda_software","EDA Software","Other"))))) -> Fabless
A177: 2015 | B177: Marvell | C177: MRVL | D177: USA | E177: fabless_networking | F177: 2.73 | G177: 27.5 | H177: 0.75 | I177: 0.33 | J177: 0.27 | K177: =IF(A177>=2025,"Forecast","Actual") -> Actual | L177: =IF(F177=0,0,I177/F177*100) -> 12.087912 | M177: =IF(F177=0,0,J177/F177*100) -> 9.8901099 | N177: =IF(LEFT(E177,7)="fabless","Fabless",IF(LEFT(E177,9)="equipment","Equipment",IF(E177="foundry","Manufacturer",IF(LEFT(E177,3)="idm","Manufacturer",IF(E177="eda_software","EDA Software","Other"))))) -> Fabless
A178: 2016 | B178: Marvell | C178: MRVL | D178: USA | E178: fabless_networking | F178: 2.56 | G178: 27.4 | H178: 0.7 | I178: 0.31 | J178: 0.26 | K178: =IF(A178>=2025,"Forecast","Actual") -> Actual | L178: =IF(F178=0,0,I178/F178*100) -> 12.109375 | M178: =IF(F178=0,0,J178/F178*100) -> 10.15625 | N178: =IF(LEFT(E178,7)="fabless","Fabless",IF(LEFT(E178,9)="equipment","Equipment",IF(E178="foundry","Manufacturer",IF(LEFT(E178,3)="idm","Manufacturer",IF(E178="eda_software","EDA Software","Other"))))) -> Fabless
A179: 2017 | B179: Marvell | C179: MRVL | D179: USA | E179: fabless_networking | F179: 2.58 | G179: 25.7 | H179: 0.66 | I179: 0.31 | J179: 0.26 | K179: =IF(A179>=2025,"Forecast","Actual") -> Actual | L179: =IF(F179=0,0,I179/F179*100) -> 12.015504 | M179: =IF(F179=0,0,J179/F179*100) -> 10.077519 | N179: =IF(LEFT(E179,7)="fabless","Fabless",IF(LEFT(E179,9)="equipment","Equipment",IF(E179="foundry","Manufacturer",IF(LEFT(E179,3)="idm","Manufacturer",IF(E179="eda_software","EDA Software","Other"))))) -> Fabless
A180: 2018 | B180: Marvell | C180: MRVL | D180: USA | E180: fabless_networking | F180: 2.42 | G180: 25.8 | H180: 0.62 | I180: 0.29 | J180: 0.24 | K180: =IF(A180>=2025,"Forecast","Actual") -> Actual | L180: =IF(F180=0,0,I180/F180*100) -> 11.983471 | M180: =IF(F180=0,0,J180/F180*100) -> 9.9173554 | N180: =IF(LEFT(E180,7)="fabless","Fabless",IF(LEFT(E180,9)="equipment","Equipment",IF(E180="foundry","Manufacturer",IF(LEFT(E180,3)="idm","Manufacturer",IF(E180="eda_software","EDA Software","Other"))))) -> Fabless
A181: 2019 | B181: Marvell | C181: MRVL | D181: USA | E181: fabless_networking | F181: 2.63 | G181: 24.6 | H181: 0.65 | I181: 0.32 | J181: 0.26 | K181: =IF(A181>=2025,"Forecast","Actual") -> Actual | L181: =IF(F181=0,0,I181/F181*100) -> 12.1673 | M181: =IF(F181=0,0,J181/F181*100) -> 9.8859316 | N181: =IF(LEFT(E181,7)="fabless","Fabless",IF(LEFT(E181,9)="equipment","Equipment",IF(E181="foundry","Manufacturer",IF(LEFT(E181,3)="idm","Manufacturer",IF(E181="eda_software","EDA Software","Other"))))) -> Fabless
A182: 2020 | B182: Marvell | C182: MRVL | D182: USA | E182: fabless_networking | F182: 2.99 | G182: 26.2 | H182: 0.78 | I182: 0.36 | J182: 0.3 | K182: =IF(A182>=2025,"Forecast","Actual") -> Actual | L182: =IF(F182=0,0,I182/F182*100) -> 12.040134 | M182: =IF(F182=0,0,J182/F182*100) -> 10.033445 | N182: =IF(LEFT(E182,7)="fabless","Fabless",IF(LEFT(E182,9)="equipment","Equipment",IF(E182="foundry","Manufacturer",IF(LEFT(E182,3)="idm","Manufacturer",IF(E182="eda_software","EDA Software","Other"))))) -> Fabless
A183: 2021 | B183: Marvell | C183: MRVL | D183: USA | E183: fabless_networking | F183: 4.59 | G183: 21.8 | H183: 1 | I183: 0.55 | J183: 0.46 | K183: =IF(A183>=2025,"Forecast","Actual") -> Actual | L183: =IF(F183=0,0,I183/F183*100) -> 11.982571 | M183: =IF(F183=0,0,J183/F183*100) -> 10.021786 | N183: =IF(LEFT(E183,7)="fabless","Fabless",IF(LEFT(E183,9)="equipment","Equipment",IF(E183="foundry","Manufacturer",IF(LEFT(E183,3)="idm","Manufacturer",IF(E183="eda_software","EDA Software","Other"))))) -> Fabless
... A341: 2026 | B341: NXP Semiconductors | C341: NXPI | D341: NLD | E341: idm_automotive | F341: 15.68 | G341: 19.5 | H341: 3.06 | I341: 1.88 | J341: 2.35 | K341: =IF(A341>=2025,"Forecast","Actual") -> Forecast | L341: =IF(F341=0,0,I341/F341*100) -> 11.989796 | M341: =IF(F341=0,0,J341/F341*100) -> 14.987245 | N341: =IF(LEFT(E341,7)="fabless","Fabless",IF(LEFT(E341,9)="equipment","Equipment",IF(E341="foundry","Manufacturer",IF(LEFT(E341,3)="idm","Manufacturer",IF(E341="eda_software","EDA Software","Other"))))) -> Manufacturer
...

Sheet RAW_Price
A1: Year_month | B1: Year | C1: Product | D1: Currency | E1: Unit | F1: Price | G1: Product_Category
A2: 2014-01 | B2: 2014 | C2: DRAM_DDR4_8Gb | D2: USD | E2: USD/chip | F2: 4.36 | G2: =IF(LEFT(C2,4)="DRAM","Memory - DRAM",IF(LEFT(C2,4)="NAND","Memory - NAND",IF(LEFT(C2,3)="HBM","Memory - HBM","GPU"))) -> Memory - DRAM
A3: 2014-02 | B3: 2014 | C3: DRAM_DDR4_8Gb | D3: USD | E3: USD/chip | F3: 4.5 | G3: =IF(LEFT(C3,4)="DRAM","Memory - DRAM",IF(LEFT(C3,4)="NAND","Memory - NAND",IF(LEFT(C3,3)="HBM","Memory - HBM","GPU"))) -> Memory - DRAM
A4: 2014-03 | B4: 2014 | C4: DRAM_DDR4_8Gb | D4: USD | E4: USD/chip | F4: 4.39 | G4: =IF(LEFT(C4,4)="DRAM","Memory - DRAM",IF(LEFT(C4,4)="NAND","Memory - NAND",IF(LEFT(C4,3)="HBM","Memory - HBM","GPU"))) -> Memory - DRAM
A5: 2014-04 | B5: 2014 | C5: DRAM_DDR4_8Gb | D5: USD | E5: USD/chip | F5: 3.97 | G5: =IF(LEFT(C5,4)="DRAM","Memory - DRAM",IF(LEFT(C5,4)="NAND","Memory - NAND",IF(LEFT(C5,3)="HBM","Memory - HBM","GPU"))) -> Memory - DRAM
A6: 2014-05 | B6: 2014 | C6: DRAM_DDR4_8Gb | D6: USD | E6: USD/chip | F6: 4.02 | G6: =IF(LEFT(C6,4)="DRAM","Memory - DRAM",IF(LEFT(C6,4)="NAND","Memory - NAND",IF(LEFT(C6,3)="HBM","Memory - HBM","GPU"))) -> Memory - DRAM
A7: 2014-06 | B7: 2014 | C7: DRAM_DDR4_8Gb | D7: USD | E7: USD/chip | F7: 3.95 | G7: =IF(LEFT(C7,4)="DRAM","Memory - DRAM",IF(LEFT(C7,4)="NAND","Memory - NAND",IF(LEFT(C7,3)="HBM","Memory - HBM","GPU"))) -> Memory - DRAM
A8: 2014-07 | B8: 2014 | C8: DRAM_DDR4_8Gb | D8: USD | E8: USD/chip | F8: 3.9 | G8: =IF(LEFT(C8,4)="DRAM","Memory - DRAM",IF(LEFT(C8,4)="NAND","Memory - NAND",IF(LEFT(C8,3)="HBM","Memory - HBM","GPU"))) -> Memory - DRAM
A9: 2014-08 | B9: 2014 | C9: DRAM_DDR4_8Gb | D9: USD | E9: USD/chip | F9: 3.65 | G9: =IF(LEFT(C9,4)="DRAM","Memory - DRAM",IF(LEFT(C9,4)="NAND","Memory - NAND",IF(LEFT(C9,3)="HBM","Memory - HBM","GPU"))) -> Memory - DRAM
A10: 2014-09 | B10: 2014 | C10: DRAM_DDR4_8Gb | D10: USD | E10: USD/chip | F10: 3.67 | G10: =IF(LEFT(C10,4)="DRAM","Memory - DRAM",IF(LEFT(C10,4)="NAND","Memory - NAND",IF(LEFT(C10,3)="HBM","Memory - HBM","GPU"))) -> Memory - DRAM
A11: 2014-10 | B11: 2014 | C11: DRAM_DDR4_8Gb | D11: USD | E11: USD/chip | F11: 3.57 | G11: =IF(LEFT(C11,4)="DRAM","Memory - DRAM",IF(LEFT(C11,4)="NAND","Memory - NAND",IF(LEFT(C11,3)="HBM","Memory - HBM","GPU"))) -> Memory - DRAM
A12: 2014-11 | B12: 2014 | C12: DRAM_DDR4_8Gb | D12: USD | E12: USD/chip | F12: 3.7 | G12: =IF(LEFT(C12,4)="DRAM","Memory - DRAM",IF(LEFT(C12,4)="NAND","Memory - NAND",IF(LEFT(C12,3)="HBM","Memory - HBM","GPU"))) -> Memory - DRAM
A13: 2014-12 | B13: 2014 | C13: DRAM_DDR4_8Gb | D13: USD | E13: USD/chip | F13: 3.61 | G13: =IF(LEFT(C13,4)="DRAM","Memory - DRAM",IF(LEFT(C13,4)="NAND","Memory - NAND",IF(LEFT(C13,3)="HBM","Memory - HBM","GPU"))) -> Memory - DRAM
... A406: 2026-04 | B406: 2026 | C406: NVIDIA_B200 | D406: USD | E406: USD/unit | F406: 30295.89 | G406: =IF(LEFT(C406,4)="DRAM","Memory - DRAM",IF(LEFT(C406,4)="NAND","Memory - NAND",IF(LEFT(C406,3)="HBM","Memory - HBM","GPU"))) -> GPU

Sheet RAW_Export
A1: Control_id | B1: Date | C1: Year | D1: Month | E1: Imposing_country | F1: Target | G1: Policy_name | H1: Severity_score | I1: Description | J1: Is_us_action | K1: Is_china_action | L1: Is_netherlands_action | M1: Is_trump_1_0 | N1: Is_biden | O1: Is_trump_2_0 | P1: Severity_Label | Q1: Admin_Era
A2: EC001 | B2: 43313 | C2: 2018 | D2: 8 | E2: USA | F2: ZTE | G2: Entity List action | H2: 5 | I2: ZTE banned then settled, $1.4B fine | J2: 1 | K2: 0 | L2: 0 | M2: 1 | N2: 0 | O2: 0 | P2: =IF(H2>=9,"Critical",IF(H2>=7,"High",IF(H2>=5,"Medium","Low"))) -> Medium | Q2: =IF(O2=1,"Trump 2.0",IF(N2=1,"Biden",IF(M2=1,"Trump 1.0","Other"))) -> Trump 1.0
A3: EC002 | B3: 43600 | C3: 2019 | D3: 5 | E3: USA | F3: Huawei | G3: Huawei Entity List | H3: 9 | I3: Huawei + 70 affiliates banned | J3: 1 | K3: 0 | L3: 0 | M3: 1 | N3: 0 | O3: 0 | P3: =IF(H3>=9,"Critical",IF(H3>=7,"High",IF(H3>=5,"Medium","Low"))) -> Critical | Q3: =IF(O3=1,"Trump 2.0",IF(N3=1,"Biden",IF(M3=1,"Trump 1.0","Other"))) -> Trump 1.0
A4: EC003 | B4: 43606 | C4: 2019 | D4: 5 | E4: USA | F4: Huawei | G4: TGL granted | H4: 3 | I4: 90-day Temporary General License | J4: 1 | K4: 0 | L4: 0 | M4: 1 | N4: 0 | O4: 0 | P4: =IF(H4>=9,"Critical",IF(H4>=7,"High",IF(H4>=5,"Medium","Low"))) -> Low | Q4: =IF(O4=1,"Trump 2.0",IF(N4=1,"Biden",IF(M4=1,"Trump 1.0","Other"))) -> Trump 1.0
A5: EC004 | B5: 43966 | C5: 2020 | D5: 5 | E5: USA | F5: Huawei | G5: FDPR Direct Product Rule | H5: 9 | I5: Foreign Direct Product Rule blocks TSMC-Huawei | J5: 1 | K5: 0 | L5: 0 | M5: 1 | N5: 0 | O5: 0 | P5: =IF(H5>=9,"Critical",IF(H5>=7,"High",IF(H5>=5,"Medium","Low"))) -> Critical | Q5: =IF(O5=1,"Trump 2.0",IF(N5=1,"Biden",IF(M5=1,"Trump 1.0","Other"))) -> Trump 1.0
A6: EC005 | B6: 44089 | C6: 2020 | D6: 9 | E6: USA | F6: Huawei | G6: FDPR expanded | H6: 8 | I6: Expanded FDPR cuts off Huawei from all chips | J6: 1 | K6: 0 | L6: 0 | M6: 1 | N6: 0 | O6: 0 | P6: =IF(H6>=9,"Critical",IF(H6>=7,"High",IF(H6>=5,"Medium","Low"))) -> High | Q6: =IF(O6=1,"Trump 2.0",IF(N6=1,"Biden",IF(M6=1,"Trump 1.0","Other"))) -> Trump 1.0
A7: EC006 | B7: 44183 | C7: 2020 | D7: 12 | E7: USA | F7: SMIC | G7: Entity List addition | H7: 7 | I7: SMIC added with restricted EUV access | J7: 1 | K7: 0 | L7: 0 | M7: 1 | N7: 0 | O7: 0 | P7: =IF(H7>=9,"Critical",IF(H7>=7,"High",IF(H7>=5,"Medium","Low"))) -> High | Q7: =IF(O7=1,"Trump 2.0",IF(N7=1,"Biden",IF(M7=1,"Trump 1.0","Other"))) -> Trump 1.0
A8: EC007 | B8: 44294 | C8: 2021 | D8: 4 | E8: USA | F8: Phytium | G8: Supercomputer EL | H8: 5 | I8: 7 Chinese supercomputer firms added | J8: 1 | K8: 0 | L8: 0 | M8: 0 | N8: 1 | O8: 0 | P8: =IF(H8>=9,"Critical",IF(H8>=7,"High",IF(H8>=5,"Medium","Low"))) -> Medium | Q8: =IF(O8=1,"Trump 2.0",IF(N8=1,"Biden",IF(M8=1,"Trump 1.0","Other"))) -> Biden
A9: EC008 | B9: 44782 | C9: 2022 | D9: 8 | E9: USA | F9: CHIPS_Act | G9: CHIPS Act signed | H9: 10 | I9: $52B for US chip manufacturing | J9: 1 | K9: 0 | L9: 0 | M9: 0 | N9: 1 | O9: 0 | P9: =IF(H9>=9,"Critical",IF(H9>=7,"High",IF(H9>=5,"Medium","Low"))) -> Critical | Q9: =IF(O9=1,"Trump 2.0",IF(N9=1,"Biden",IF(M9=1,"Trump 1.0","Other"))) -> Biden
A10: EC009 | B10: 44804 | C10: 2022 | D10: 8 | E10: USA | F10: NVIDIA_AMD | G10: AI chip restrictions | H10: 8 | I10: A100/H100 export restrictions to China | J10: 1 | K10: 0 | L10: 0 | M10: 0 | N10: 1 | O10: 0 | P10: =IF(H10>=9,"Critical",IF(H10>=7,"High",IF(H10>=5,"Medium","Low"))) -> High | Q10: =IF(O10=1,"Trump 2.0",IF(N10=1,"Biden",IF(M10=1,"Trump 1.0","Other"))) -> Biden
A11: EC010 | B11: 44841 | C11: 2022 | D11: 10 | E11: USA | F11: BIS_China | G11: Comprehensive controls | H11: 10 | I11: Sweeping export controls on advanced computing | J11: 1 | K11: 0 | L11: 0 | M11: 0 | N11: 1 | O11: 0 | P11: =IF(H11>=9,"Critical",IF(H11>=7,"High",IF(H11>=5,"Medium","Low"))) -> Critical | Q11: =IF(O11=1,"Trump 2.0",IF(N11=1,"Biden",IF(M11=1,"Trump 1.0","Other"))) -> Biden
A12: EC011 | B12: 44910 | C12: 2022 | D12: 12 | E12: USA | F12: YMTC_Entity | G12: YMTC + 31 companies | H12: 8 | I12: YMTC Entity List, '36 Chinese entities' | J12: 1 | K12: 0 | L12: 0 | M12: 0 | N12: 1 | O12: 0 | P12: =IF(H12>=9,"Critical",IF(H12>=7,"High",IF(H12>=5,"Medium","Low"))) -> High | Q12: =IF(O12=1,"Trump 2.0",IF(N12=1,"Biden",IF(M12=1,"Trump 1.0","Other"))) -> Biden
A13: EC012 | B13: 44953 | C13: 2023 | D13: 1 | E13: USA | F13: Netherlands_Japan | G13: ASML/Tokyo Electron deal | H13: 9 | I13: NL/JP agree on chip equipment restrictions | J13: 1 | K13: 0 | L13: 0 | M13: 0 | N13: 1 | O13: 0 | P13: =IF(H13>=9,"Critical",IF(H13>=7,"High",IF(H13>=5,"Medium","Low"))) -> Critical | Q13: =IF(O13=1,"Trump 2.0",IF(N13=1,"Biden",IF(M13=1,"Trump 1.0","Other"))) -> Biden
... A35: EC034 | B35: 46142 | C35: 2026 | D35: 4 | E35: CHN | F35: REE_tightened | G35: Heavy REE near-total ban | H35: 8 | I35: China severs heavy rare earth exports | J35: 0 | K35: 1 | L35: 0 | M35: 0 | N35: 0 | O35: 1 | P35: =IF(H35>=9,"Critical",IF(H35>=7,"High",IF(H35>=5,"Medium","Low"))) -> High | Q35: =IF(O35=1,"Trump 2.0",IF(N35=1,"Biden",IF(M35=1,"Trump 1.0","Other"))) -> Trump 2.0

Sheet RAW_Fab
A1: Year | B1: Company | C1: Country_iso3 | D1: Process_node_nm | E1: Fab_type | F1: Monthly_wafer_capacity | G1: fab_started_year | H1: Node_Category | I1: Regions
A2: 2022 | B2: TSMC | C2: TWN | D2: 3 | E2: logic_leading | F2: 0 | G2: 2022 | H2: =IF(D2<=5,"Leading Edge (3-5nm)",IF(D2<=16,"Advanced (7-16nm)",IF(D2<=28,"Mature (22-28nm)","Legacy (40nm+)"))) -> Leading Edge (3-5nm) | I2: =IF(C2="TWN","Taiwan",IF(C2="KOR","South Korea",IF(C2="USA","USA",IF(C2="CHN","China",IF(C2="JPN","Japan",IF(C2="DEU","Europe",IF(C2="NLD","Europe",IF(C2="ITA","Europe",IF(C2="ISR","Middle East","Other"))))))))) -> Taiwan
A3: 2023 | B3: TSMC | C3: TWN | D3: 3 | E3: logic_leading | F3: 38445 | G3: 2022 | H3: =IF(D3<=5,"Leading Edge (3-5nm)",IF(D3<=16,"Advanced (7-16nm)",IF(D3<=28,"Mature (22-28nm)","Legacy (40nm+)"))) -> Leading Edge (3-5nm) | I3: =IF(C3="TWN","Taiwan",IF(C3="KOR","South Korea",IF(C3="USA","USA",IF(C3="CHN","China",IF(C3="JPN","Japan",IF(C3="DEU","Europe",IF(C3="NLD","Europe",IF(C3="ITA","Europe",IF(C3="ISR","Middle East","Other"))))))))) -> Taiwan
A4: 2024 | B4: TSMC | C4: TWN | D4: 3 | E4: logic_leading | F4: 80106 | G4: 2022 | H4: =IF(D4<=5,"Leading Edge (3-5nm)",IF(D4<=16,"Advanced (7-16nm)",IF(D4<=28,"Mature (22-28nm)","Legacy (40nm+)"))) -> Leading Edge (3-5nm) | I4: =IF(C4="TWN","Taiwan",IF(C4="KOR","South Korea",IF(C4="USA","USA",IF(C4="CHN","China",IF(C4="JPN","Japan",IF(C4="DEU","Europe",IF(C4="NLD","Europe",IF(C4="ITA","Europe",IF(C4="ISR","Middle East","Other"))))))))) -> Taiwan
A5: 2025 | B5: TSMC | C5: TWN | D5: 3 | E5: logic_leading | F5: 129646 | G5: 2022 | H5: =IF(D5<=5,"Leading Edge (3-5nm)",IF(D5<=16,"Advanced (7-16nm)",IF(D5<=28,"Mature (22-28nm)","Legacy (40nm+)"))) -> Leading Edge (3-5nm) | I5: =IF(C5="TWN","Taiwan",IF(C5="KOR","South Korea",IF(C5="USA","USA",IF(C5="CHN","China",IF(C5="JPN","Japan",IF(C5="DEU","Europe",IF(C5="NLD","Europe",IF(C5="ITA","Europe",IF(C5="ISR","Middle East","Other"))))))))) -> Taiwan
A6: 2026 | B6: TSMC | C6: TWN | D6: 3 | E6: logic_leading | F6: 136143 | G6: 2022 | H6: =IF(D6<=5,"Leading Edge (3-5nm)",IF(D6<=16,"Advanced (7-16nm)",IF(D6<=28,"Mature (22-28nm)","Legacy (40nm+)"))) -> Leading Edge (3-5nm) | I6: =IF(C6="TWN","Taiwan",IF(C6="KOR","South Korea",IF(C6="USA","USA",IF(C6="CHN","China",IF(C6="JPN","Japan",IF(C6="DEU","Europe",IF(C6="NLD","Europe",IF(C6="ITA","Europe",IF(C6="ISR","Middle East","Other"))))))))) -> Taiwan
A7: 2020 | B7: TSMC | C7: TWN | D7: 5 | E7: logic_leading | F7: 0 | G7: 2020 | H7: =IF(D7<=5,"Leading Edge (3-5nm)",IF(D7<=16,"Advanced (7-16nm)",IF(D7<=28,"Mature (22-28nm)","Legacy (40nm+)"))) -> Leading Edge (3-5nm) | I7: =IF(C7="TWN","Taiwan",IF(C7="KOR","South Korea",IF(C7="USA","USA",IF(C7="CHN","China",IF(C7="JPN","Japan",IF(C7="DEU","Europe",IF(C7="NLD","Europe",IF(C7="ITA","Europe",IF(C7="ISR","Middle East","Other"))))))))) -> Taiwan
A8: 2021 | B8: TSMC | C8: TWN | D8: 5 | E8: logic_leading | F8: 53296 | G8: 2020 | H8: =IF(D8<=5,"Leading Edge (3-5nm)",IF(D8<=16,"Advanced (7-16nm)",IF(D8<=28,"Mature (22-28nm)","Legacy (40nm+)"))) -> Leading Edge (3-5nm) | I8: =IF(C8="TWN","Taiwan",IF(C8="KOR","South Korea",IF(C8="USA","USA",IF(C8="CHN","China",IF(C8="JPN","Japan",IF(C8="DEU","Europe",IF(C8="NLD","Europe",IF(C8="ITA","Europe",IF(C8="ISR","Middle East","Other"))))))))) -> Taiwan
A9: 2022 | B9: TSMC | C9: TWN | D9: 5 | E9: logic_leading | F9: 95116 | G9: 2020 | H9: =IF(D9<=5,"Leading Edge (3-5nm)",IF(D9<=16,"Advanced (7-16nm)",IF(D9<=28,"Mature (22-28nm)","Legacy (40nm+)"))) -> Leading Edge (3-5nm) | I9: =IF(C9="TWN","Taiwan",IF(C9="KOR","South Korea",IF(C9="USA","USA",IF(C9="CHN","China",IF(C9="JPN","Japan",IF(C9="DEU","Europe",IF(C9="NLD","Europe",IF(C9="ITA","Europe",IF(C9="ISR","Middle East","Other"))))))))) -> Taiwan
A10: 2023 | B10: TSMC | C10: TWN | D10: 5 | E10: logic_leading | F10: 163173 | G10: 2020 | H10: =IF(D10<=5,"Leading Edge (3-5nm)",IF(D10<=16,"Advanced (7-16nm)",IF(D10<=28,"Mature (22-28nm)","Legacy (40nm+)"))) -> Leading Edge (3-5nm) | I10: =IF(C10="TWN","Taiwan",IF(C10="KOR","South Korea",IF(C10="USA","USA",IF(C10="CHN","China",IF(C10="JPN","Japan",IF(C10="DEU","Europe",IF(C10="NLD","Europe",IF(C10="ITA","Europe",IF(C10="ISR","Middle East","Other"))))))))) -> Taiwan
A11: 2024 | B11: TSMC | C11: TWN | D11: 5 | E11: logic_leading | F11: 146070 | G11: 2020 | H11: =IF(D11<=5,"Leading Edge (3-5nm)",IF(D11<=16,"Advanced (7-16nm)",IF(D11<=28,"Mature (22-28nm)","Legacy (40nm+)"))) -> Leading Edge (3-5nm) | I11: =IF(C11="TWN","Taiwan",IF(C11="KOR","South Korea",IF(C11="USA","USA",IF(C11="CHN","China",IF(C11="JPN","Japan",IF(C11="DEU","Europe",IF(C11="NLD","Europe",IF(C11="ITA","Europe",IF(C11="ISR","Middle East","Other"))))))))) -> Taiwan
A12: 2025 | B12: TSMC | C12: TWN | D12: 5 | E12: logic_leading | F12: 165947 | G12: 2020 | H12: =IF(D12<=5,"Leading Edge (3-5nm)",IF(D12<=16,"Advanced (7-16nm)",IF(D12<=28,"Mature (22-28nm)","Legacy (40nm+)"))) -> Leading Edge (3-5nm) | I12: =IF(C12="TWN","Taiwan",IF(C12="KOR","South Korea",IF(C12="USA","USA",IF(C12="CHN","China",IF(C12="JPN","Japan",IF(C12="DEU","Europe",IF(C12="NLD","Europe",IF(C12="ITA","Europe",IF(C12="ISR","Middle East","Other"))))))))) -> Taiwan
A13: 2026 | B13: TSMC | C13: TWN | D13: 5 | E13: logic_leading | F13: 165561 | G13: 2020 | H13: =IF(D13<=5,"Leading Edge (3-5nm)",IF(D13<=16,"Advanced (7-16nm)",IF(D13<=28,"Mature (22-28nm)","Legacy (40nm+)"))) -> Leading Edge (3-5nm) | I13: =IF(C13="TWN","Taiwan",IF(C13="KOR","South Korea",IF(C13="USA","USA",IF(C13="CHN","China",IF(C13="JPN","Japan",IF(C13="DEU","Europe",IF(C13="NLD","Europe",IF(C13="ITA","Europe",IF(C13="ISR","Middle East","Other"))))))))) -> Taiwan
... A314: 2026 | B314: Hua Hong | C314: CHN | D314: 28 | E314: logic_mature | F314: 70440 | G314: 2020 | H314: =IF(D314<=5,"Leading Edge (3-5nm)",IF(D314<=16,"Advanced (7-16nm)",IF(D314<=28,"Mature (22-28nm)","Legacy (40nm+)"))) -> Mature (22-28nm) | I314: =IF(C314="TWN","Taiwan",IF(C314="KOR","South Korea",IF(C314="USA","USA",IF(C314="CHN","China",IF(C314="JPN","Japan",IF(C314="DEU","Europe",IF(C314="NLD","Europe",IF(C314="ITA","Europe",IF(C314="ISR","Middle East","Other"))))))))) -> China

Sheet CALC
A1: Label | B1: Formula
A2: Total Industry Revenue 2024 (USD Bn) | B2: =SUMIFS(RAW_Fin!F:F,RAW_Fin!A:A,"2024",RAW_Fin!K:K,"Actual") -> 828.51
A3: Highest Operating Margin 2024 (%) | B3: =_xlfn.MAXIFS(RAW_Fin!G:G,RAW_Fin!A:A,"2024",RAW_Fin!K:K,"Actual") -> 59.5
A4: NVIDIA H100 Peak Price (USD) | B4: =_xlfn.MAXIFS(RAW_Price!F:F,RAW_Price!C:C,"NVIDIA_H100") -> 35640.01
A5: Total Export Control Actions | B5: =COUNTA(RAW_Export!A:A)-1 -> 34
A8: PT1 - AI Chip Revenue by Vendor by Year
A9: Sum of Estimated_revenue_usd_m | B9: Year
A10: Vendor | B10: 2020 | C10: 2021 | D10: 2022 | E10: 2023 | F10: 2024 | G10: 2025 | H10: 2026 | I10: Grand Total
A11: AMD | C11: 0.3 | D11: 15.4 | E11: 10.7 | F11: 7518.2 | G11: 7812.5 | H11: 3809.5 | I11: 19166.6
A12: AWS | D12: 0 | E12: 2737.8 | F12: 1671.6 | G12: 2008.9 | H12: 1555.5 | I12: 7973.8
A13: Google | B13: 11.2 | C13: 7.6 | D13: 20.3 | E13: 914.1 | F13: 11431.3 | G13: 7379.7 | H13: 3601.6 | I13: 23365.8
A14: Huawei | B14: 16.2 | C14: 12.2 | D14: 5.1 | E14: 477.9 | F14: 4981.7 | G14: 4195 | H14: 2019.4 | I14: 11707.5
A15: NVIDIA | B15: 572.7 | C15: 3115.6 | D15: 2226.6 | E15: 19454 | F15: 83456.8 | G15: 87834 | H15: 57404.8 | I15: 254064.5
A16: Grand Total | B16: 600.1 | C16: 3135.7 | D16: 2267.4 | E16: 23594.5 | F16: 109059.6 | G16: 109230.1 | H16: 68390.8 | I16: 316278.2
A25: Data_Type | B25: Actual
A26: PT2 - Company Revenue Trends
A27: Sum of Revenue_usd_bn | B27: Company_name
A28: Year | B28: AMD | C28: Analog Devices | D28: Applied Materials | E28: ASML | F28: Broadcom | G28: Cadence | H28: Cerebras Systems | I28: ChangXin Memory (CXMT) | J28: GlobalFoundries | K28: Graphcore | L28: Groq | M28: HiSilicon (Huawei) | N28: Hua Hong | O28: Infineon | P28: Intel | Q28: KLA | R28: Lam Research | S28: Marvell | T28: MediaTek | U28: Microchip | V28: Micron | W28: NVIDIA | X28: NXP Semiconductors | Y28: Onsemi | Z28: Qualcomm | AA28: Renesas | AB28: SambaNova | AC28: Samsung Foundry | AD28: Samsung Memory | AE28: SCREEN Holdings | AF28: SK Hynix | AG28: SMIC | AH28: STMicroelectronics | AI28: Synopsys | AJ28: Tenstorrent | AK28: Texas Instruments | AL28: Tokyo Electron | AM28: TSMC | AN28: UMC | AO28: Yangtze Memory (YMTC) | AP28: Grand Total
A29: 2010 | B29: 6.11 | C29: 2.88 | D29: 9.39 | E29: 6.65 | F29: 2.99 | G29: 0.95 | J29: 3.59 | M29: 0.96 | N29: 0.63 | O29: 4.57 | P29: 44.33 | Q29: 1.74 | R29: 2.57 | S29: 3.36 | T29: 3.56 | U29: 1.49 | V29: 8.78 | W29: 3.43 | X29: 4.48 | Y29: 2.27 | Z29: 10.65 | AA29: 12.3 | AC29: 3.06 | AD29: 31.08 | AE29: 1.83 | AF29: 10.61 | AG29: 1.62 | AH29: 9.87 | AI29: 1.34 | AK29: 13.26 | AL29: 6.88 | AM29: 13.42 | AN29: 4.35 | AP29: 235
A30: 2011 | B30: 5.85 | C30: 3.02 | D30: 9.56 | E30: 6.44 | F30: 3.94 | G30: 1.11 | J30: 3.66 | M30: 1.61 | N30: 0.62 | O30: 4.54 | P30: 45.66 | Q30: 2.08 | R30: 3.23 | S30: 3.43 | T30: 4.23 | U30: 1.56 | V30: 10.04 | W30: 3.75 | X30: 4.76 | Y30: 2.54 | Z30: 13.44 | AA30: 11.42 | AC30: 3.69 | AD30: 32.71 | AE30: 1.86 | AF30: 11.58 | AG30: 1.83 | AH30: 9.41 | AI30: 1.55 | AK30: 13.76 | AL30: 6.28 | AM30: 16.32 | AN30: 4.32 | AP30: 249.8
A31: 2012 | B31: 5.36 | C31: 3.17 | D31: 9.32 | E31: 6.59 | F31: 4.42 | G31: 1.17 | J31: 3.99 | M31: 2.21 | N31: 0.62 | O31: 5.11 | P31: 50.66 | Q31: 2.04 | R31: 3.71 | S31: 3.4 | T31: 4.89 | U31: 1.76 | V31: 11.66 | W31: 3.95 | X31: 5.37 | Y31: 2.7 | Z31: 15.75 | AA31: 9.87 | AC31: 4.29 | AD31: 34.69 | AE31: 1.97 | AF31: 13.32 | AG31: 1.86 | AH31: 9.17 | AI31: 1.77 | AK31: 13.87 | AL31: 6.1 | AM31: 17.56 | AN31: 4.35 | AP31: 266.67
A32: 2013 | B32: 5.14 | C32: 3.24 | D32: 9.12 | E32: 6.51 | F32: 5.47 | G32: 1.31 | J32: 4.42 | M32: 2.79 | N32: 0.65 | O32: 5.56 | P32: 50.78 | Q32: 2.34 | R32: 4.26 | S32: 3.01 | T32: 5.56 | U32: 1.91 | V32: 13.16 | W32: 4.61 | X32: 5.7 | Y32: 3.19 | Z32: 20.68 | AA32: 9.22 | AC32: 5.21 | AD32: 36.29 | AE32: 2.1 | AF32: 14.58 | AG32: 1.84 | AH32: 8.17 | AI32: 1.98 | AK32: 13.63 | AL32: 5.79 | AM32: 21.36 | AN32: 4.64 | AP32: 284.22
A33: 2014 | B33: 4.5 | C33: 3.33 | D33: 8.91 | E33: 6.71 | F33: 6.13 | G33: 1.55 | J33: 4.64 | M33: 3.35 | N33: 0.68 | O33: 5.52 | P33: 50.47 | Q33: 2.57 | R33: 4.49 | S33: 2.75 | T33: 5.99 | U33: 1.92 | V33: 14.64 | W33: 4.68 | X33: 5.86 | Y33: 3.17 | Z33: 21.48 | AA33: 7.89 | AC33: 5.69 | AD33: 39.06 | AE33: 2.31 | AF33: 15.24 | AG33: 2.03 | AH33: 7.56 | AI33: 2.03 | AK33: 13.54 | AL33: 5.53 | AM33: 23.93 | AN33: 4.62 | AP33: 292.77
A34: 2015 | B34: 3.96 | C34: 3.39 | D34: 9.41 | E34: 7.11 | F34: 6.99 | G34: 1.76 | J34: 5.09 | M34: 3.92 | N34: 0.7 | O34: 6.04 | P34: 52.71 | Q34: 2.77 | R34: 5.15 | S34: 2.73 | T34: 6.41 | U34: 2.14 | V34: 15.83 | W34: 5.2 | X34: 5.94 | Y34: 3.57 | Z34: 27.28 | AA34: 7.07 | AC34: 6.52 | AD34: 38.92 | AE34: 2.23 | AF34: 17.49 | AG34: 2.16 | AH34: 7.06 | AI34: 2.25 | AK34: 12.63 | AL34: 5.26 | AM34: 27.31 | AN34: 4.52 | AP34: 311.52
A35: 2016 | B35: 4.91 | C35: 4.24 | D35: 12.27 | E35: 8.21 | F35: 11.09 | G35: 1.81 | J35: 5.47 | M35: 5 | N35: 0.76 | O35: 6.56 | P35: 61.27 | Q35: 3.14 | R35: 7.22 | S35: 2.56 | T35: 7 | U35: 2.82 | V35: 20.41 | W35: 6.49 | X35: 7.47 | Y35: 4.46 | Z35: 23.97 | AA35: 7.2 | AC35: 8.55 | AD35: 52.14 | AE35: 2.5 | AF35: 22.88 | AG35: 2.68 | AH35: 7.98 | AI35: 2.51 | AK35: 14.5 | AL35: 7.3 | AM35: 29.19 | AN35: 4.71 | AP35: 369.27
A36: 2017 | B36: 5.64 | C36: 5.07 | D36: 14.44 | E36: 10.65 | F36: 16.26 | G36: 1.94 | J36: 5.74 | M36: 6.61 | N36: 0.88 | O36: 8.03 | P36: 66.18 | Q36: 3.65 | R36: 8.98 | S36: 2.58 | T36: 7.37 | U36: 3.29 | V36: 26.52 | W36: 8.24 | X36: 7.89 | Y36: 5.21 | Z36: 24.72 | AA36: 6.83 | AC36: 10.38 | AD36: 63.85 | AE36: 2.68 | AF36: 30.12 | AG36: 2.99 | AH36: 8.63 | AI36: 2.8 | AK36: 15.51 | AL36: 9.63 | AM36: 32.11 | AN36: 4.83 | AO36: 0.1 | AP36: 430.35
A37: 2018 | B37: 6.46 | C37: 6.19 | D37: 16.14 | E37: 12.38 | F37: 20.62 | G37: 2.16 | I37: 0.31 | J37: 5.98 | M37: 7.46 | N37: 0.85 | O37: 8.08 | P37: 66.06 | Q37: 4.05 | R37: 10.66 | S37: 2.42 | T37: 7.87 | U37: 4.05 | V37: 30.14 | W37: 9.75 | X37: 9.15 | Y37: 5.96 | Z37: 22.53 | AA37: 6.53 | AC37: 12.1 | AD37: 75.95 | AE37: 2.98 | AF37: 35.86 | AG37: 3.23 | AH37: 9.3 | AI37: 3.06 | AK37: 16.5 | AL37: 11.41 | AM37: 34.58 | AN37: 5.14 | AO37: 0.29 | AP37: 476.2
A38: 2019 | B38: 8.19 | C38: 5.91 | D38: 16.57 | E38: 13.65 | F38: 22.18 | G38: 2.46 | H38: 0 | I38: 0.94 | J38: 5.47 | K38: 0 | M38: 9.19 | N38: 0.93 | O38: 8.57 | P38: 73.31 | Q38: 4.88 | R38: 10.37 | S38: 2.63 | T38: 9.77 | U38: 4.73 | V38: 25.66 | W38: 12.67 | X38: 8.98 | Y38: 5.61 | Z38: 23.4 | AA38: 6.62 | AC38: 12.78 | AD38: 74.27 | AE38: 2.78 | AF38: 32.3 | AG38: 3.64 | AH38: 10.39 | AI38: 3.4 | AK38: 15.27 | AL38: 10.82 | AM38: 40.91 | AN38: 5.29 | AO38: 0.51 | AP38: 495.05
A39: 2020 | B39: 9.83 | C39: 5.75 | D39: 17.03 | E39: 16.17 | F39: 24.98 | G39: 2.62 | H39: 0 | I39: 1.45 | J39: 4.97 | K39: 0 | L39: 0 | M39: 10.7 | N39: 0.97 | O39: 9.07 | P39: 79.56 | Q39: 5.69 | R39: 10.08 | S39: 2.99 | T39: 10.4 | U39: 5.34 | V39: 20.26 | W39: 17.59 | X39: 8.19 | Y39: 5.1 | Z39: 23.41 | AA39: 6.82 | AB39: 0 | AC39: 14.49 | AD39: 64.28 | AE39: 2.72 | AF39: 27.17 | AG39: 3.92 | AH39: 10.08 | AI39: 3.78 | AJ39: 0 | AK39: 14.34 | AL39: 11.42 | AM39: 45.25 | AN39: 6.04 | AO39: 1.23 | AP39: 503.69
A40: 2021 | B40: 18.01 | C40: 8.76 | D40: 22.72 | E40: 20.79 | F40: 28.35 | G40: 3.22 | H40: 0.1 | I40: 2.26 | J40: 6.63 | K40: 0.07 | L40: 0 | M40: 6.76 | N40: 1.78 | O40: 11.78 | P40: 72.13 | Q40: 7.45 | R40: 13.9 | S40: 4.59 | T40: 14.24 | U40: 7.01 | V40: 24.59 | W40: 21.6 | X40: 10.73 | Y40: 7.16 | Z40: 33.61 | AA40: 8.53 | AB40: 0.02 | AC40: 16.46 | AD40: 69.3 | AE40: 3.2 | AF40: 30.7 | AG40: 5.52 | AH40: 13.03 | AI40: 4.45 | AJ40: 0.01 | AK40: 17.02 | AL40: 13.79 | AM40: 62.97 | AN40: 7.69 | AO40: 2.1 | AP40: 603.03
A41: 2022 | B41: 23 | C41: 12.2 | D41: 27.32 | E41: 23.9 | F41: 33.5 | G41: 3.52 | H41: 0.22 | I41: 3.1 | J41: 8 | K41: 0.05 | L41: 0.02 | M41: 1.97 | N41: 2.51 | O41: 14.75 | P41: 64.11 | Q41: 9.22 | R41: 16.25 | S41: 5.88 | T41: 19.46 | U41: 8 | V41: 32.09 | W41: 26.12 | X41: 13.51 | Y41: 8.36 | Z41: 44.51 | AA41: 11.35 | AB41: 0.05 | AC41: 18.03 | AD41: 75.7 | AE41: 4.03 | AF41: 34.69 | AG41: 7.09 | AH41: 16.01 | AI41: 4.82 | AJ41: 0.05 | AK41: 19.08 | AL41: 16.54 | AM41: 74.93 | AN41: 9.4 | AO41: 4.12 | AP41: 697.46
A42: 2023 | B42: 21.72 | C42: 11.78 | D42: 27.93 | E42: 30.31 | F42: 33.96 | G42: 4.03 | H42: 0.3 | I42: 4.04 | J42: 7.03 | K42: 0.05 | L42: 0.04 | M42: 4.03 | N42: 2.32 | O42: 16.68 | P42: 53.91 | Q42: 10.27 | R42: 17.39 | S42: 5.38 | T42: 13.32 | U42: 7.83 | V42: 15.17 | W42: 62.09 | X42: 13.02 | Y42: 8.3 | Z42: 36.31 | AA42: 10.31 | AB42: 0.1 | AC42: 12.36 | AD42: 50.38 | AE42: 4.22 | AF42: 25.33 | AG42: 6.72 | AH42: 17.6 | AI42: 5.71 | AJ42: 0.1 | AK42: 17.22 | AL42: 14.63 | AM42: 70.42 | AN42: 6.87 | AO42: 5.17 | AP42: 654.35
A43: 2024 | B43: 26.05 | C43: 9.47 | D43: 27.31 | E43: 31.81 | F43: 54.34 | G43: 4.47 | H43: 0.77 | I43: 5.07 | J43: 6.54 | K43: 0.05 | L43: 0.48 | M43: 9.12 | N43: 1.94 | O43: 15.35 | P43: 54.42 | Q43: 9.96 | R43: 14.85 | S43: 5.84 | T43: 17.02 | U43: 4.27 | V43: 22.96 | W43: 130.48 | X43: 12.92 | Y43: 6.87 | Z43: 39.18 | AA43: 9.34 | AB43: 0.37 | AC43: 18.09 | AD43: 74.79 | AE43: 4.26 | AF43: 51.53 | AG43: 8.2 | AH43: 12.72 | AI43: 5.91 | AJ43: 0.31 | AK43: 14.89 | AL43: 13.64 | AM43: 88.89 | AN43: 7.41 | AO43: 6.62 | AP43: 828.51
A44: Grand Total | B44: 154.73 | C44: 88.4 | D44: 237.44 | E44: 207.88 | F44: 275.22 | G44: 34.08 | H44: 1.39 | I44: 17.17 | J44: 81.22 | K44: 0.22 | L44: 0.54 | M44: 75.68 | N44: 16.84 | O44: 130.21 | P44: 885.56 | Q44: 71.85 | R44: 133.11 | S44: 53.55 | T44: 137.09 | U44: 58.12 | V44: 291.91 | W44: 320.65 | X44: 123.97 | Y44: 74.47 | Z44: 380.92 | AA44: 131.3 | AB44: 0.54 | AC44: 151.7 | AD44: 813.41 | AE44: 41.67 | AF44: 373.4 | AG44: 55.33 | AH44: 156.98 | AI44: 47.36 | AJ44: 0.47 | AK44: 225.02 | AL44: 145.02 | AM44: 599.15 | AN44: 84.18 | AO44: 20.14 | AP44: 6697.89
A46: Data_Type | B46: (ALL)
A47: Year | B47: 2024
A48: PT3 - Operating Margin Ranking 2024
A49: Company_name | B49: Average of Operating_margin_pct
A50: AMD | B50: 23.6
A51: Analog Devices | B51: 42.3
...

Sheet Charts
